Workbook

Sheet Dashboard
A1: SIMULADOR ULTRA PREMIUM - FII vs POUPANÇA
A3: Investimento Inicial | B3: 10000 | D3: Patrimônio Final FII | E3: =Sim_FII!E121 -> 126126.13
A4: Aporte Mensal | B4: 500 | D4: Patrimônio Final Poupança | E4: =Sim_Poupanca!E121 -> 100133.64
A5: Tempo (meses) | B5: 120 | D5: ROI FII | E5: =(E3-B3)/(B3+(B4*B5)) -> 1.6589447
D6: ROI Poupança | E6: =(E4-B3)/(B3+(B4*B5)) -> 1.2876234
A7: Cenário FII | B7: Moderado | D7: CAGR FII | E7: =(E3/B3)^(12/B5)-1 -> 0.28848838
D8: CAGR Poupança | E8: =(E4/B3)^(12/B5)-1 -> 0.25909355

Sheet Cenarios
A1: Cenário | B1: Taxa FII (%)
A2: Conservador | B2: 0.5
A3: Moderado | B3: 0.8
A4: Agressivo | B4: 1.2

Sheet Sim_FII
A1: Mês | B1: Saldo Inicial | C1: Aporte | D1: Rendimento | E1: Saldo Final
A2: 1 | B2: =Dashboard!B3 -> 10000 | C2: =Dashboard!B4 -> 500 | D2: =B2*(VLOOKUP(Dashboard!B7,Cenarios!A2:B4,2,FALSE())/100) -> 80 | E2: =B2+C2+D2 -> 10580
A3: =A2+1 -> 2 | B3: =E2 -> 10580 | C3: =Dashboard!B4 -> 500 | D3: =B3*(VLOOKUP(Dashboard!B7,Cenarios!A2:B4,2,FALSE())/100) -> 84.64 | E3: =B3+C3+D3 -> 11164.64
A4: =A3+1 -> 3 | B4: =E3 -> 11164.64 | C4: =Dashboard!B4 -> 500 | D4: =B4*(VLOOKUP(Dashboard!B7,Cenarios!A2:B4,2,FALSE())/100) -> 89.31712 | E4: =B4+C4+D4 -> 11753.957
A5: =A4+1 -> 4 | B5: =E4 -> 11753.957 | C5: =Dashboard!B4 -> 500 | D5: =B5*(VLOOKUP(Dashboard!B7,Cenarios!A2:B4,2,FALSE())/100) -> 94.031657 | E5: =B5+C5+D5 -> 12347.989
A6: =A5+1 -> 5 | B6: =E5 -> 12347.989 | C6: =Dashboard!B4 -> 500 | D6: =B6*(VLOOKUP(Dashboard!B7,Cenarios!A2:B4,2,FALSE())/100) -> 98.78391 | E6: =B6+C6+D6 -> 12946.773
A7: =A6+1 -> 6 | B7: =E6 -> 12946.773 | C7: =Dashboard!B4 -> 500 | D7: =B7*(VLOOKUP(Dashboard!B7,Cenarios!A2:B4,2,FALSE())/100) -> 103.57418 | E7: =B7+C7+D7 -> 13550.347
A8: =A7+1 -> 7 | B8: =E7 -> 13550.347 | C8: =Dashboard!B4 -> 500 | D8: =B8*(VLOOKUP(Dashboard!B7,Cenarios!A2:B4,2,FALSE())/100) -> 108.40277 | E8: =B8+C8+D8 -> 14158.75
A9: =A8+1 -> 8 | B9: =E8 -> 14158.75 | C9: =Dashboard!B4 -> 500 | D9: =B9*(VLOOKUP(Dashboard!B7,Cenarios!A2:B4,2,FALSE())/100) -> 113.27 | E9: =B9+C9+D9 -> 14772.02
A10: =A9+1 -> 9 | B10: =E9 -> 14772.02 | C10: =Dashboard!B4 -> 500 | D10: =B10*(VLOOKUP(Dashboard!B7,Cenarios!A2:B4,2,FALSE())/100) -> 118.17616 | E10: =B10+C10+D10 -> 15390.196
A11: =A10+1 -> 10 | B11: =E10 -> 15390.196 | C11: =Dashboard!B4 -> 500 | D11: =B11*(VLOOKUP(Dashboard!B7,Cenarios!A2:B4,2,FALSE())/100) -> 123.12157 | E11: =B11+C11+D11 -> 16013.317
A12: =A11+1 -> 11 | B12: =E11 -> 16013.317 | C12: =Dashboard!B4 -> 500 | D12: =B12*(VLOOKUP(Dashboard!B7,Cenarios!A2:B4,2,FALSE())/100) -> 128.10654 | E12: =B12+C12+D12 -> 16641.424
A13: =A12+1 -> 12 | B13: =E12 -> 16641.424 | C13: =Dashboard!B4 -> 500 | D13: =B13*(VLOOKUP(Dashboard!B7,Cenarios!A2:B4,2,FALSE())/100) -> 133.13139 | E13: =B13+C13+D13 -> 17274.555
A14: =A13+1 -> 13 | B14: =E13 -> 17274.555 | C14: =Dashboard!B4 -> 500 | D14: =B14*(VLOOKUP(Dashboard!B7,Cenarios!A2:B4,2,FALSE())/100) -> 138.19644 | E14: =B14+C14+D14 -> 17912.752
A15: =A14+1 -> 14 | B15: =E14 -> 17912.752 | C15: =Dashboard!B4 -> 500 | D15: =B15*(VLOOKUP(Dashboard!B7,Cenarios!A2:B4,2,FALSE())/100) -> 143.30201 | E15: =B15+C15+D15 -> 18556.054
A16: =A15+1 -> 15 | B16: =E15 -> 18556.054 | C16: =Dashboard!B4 -> 500 | D16: =B16*(VLOOKUP(Dashboard!B7,Cenarios!A2:B4,2,FALSE())/100) -> 148.44843 | E16: =B16+C16+D16 -> 19204.502
A17: =A16+1 -> 16 | B17: =E16 -> 19204.502 | C17: =Dashboard!B4 -> 500 | D17: =B17*(VLOOKUP(Dashboard!B7,Cenarios!A2:B4,2,FALSE())/100) -> 153.63602 | E17: =B17+C17+D17 -> 19858.138
A18: =A17+1 -> 17 | B18: =E17 -> 19858.138 | C18: =Dashboard!B4 -> 500 | D18: =B18*(VLOOKUP(Dashboard!B7,Cenarios!A2:B4,2,FALSE())/100) -> 158.86511 | E18: =B18+C18+D18 -> 20517.003
A19: =A18+1 -> 18 | B19: =E18 -> 20517.003 | C19: =Dashboard!B4 -> 500 | D19: =B19*(VLOOKUP(Dashboard!B7,Cenarios!A2:B4,2,FALSE())/100) -> 164.13603 | E19: =B19+C19+D19 -> 21181.139
A20: =A19+1 -> 19 | B20: =E19 -> 21181.139 | C20: =Dashboard!B4 -> 500 | D20: =B20*(VLOOKUP(Dashboard!B7,Cenarios!A2:B4,2,FALSE())/100) -> 169.44911 | E20: =B20+C20+D20 -> 21850.588
A21: =A20+1 -> 20 | B21: =E20 -> 21850.588 | C21: =Dashboard!B4 -> 500 | D21: =B21*(VLOOKUP(Dashboard!B7,Cenarios!A2:B4,2,FALSE())/100) -> 174.80471 | E21: =B21+C21+D21 -> 22525.393
A22: =A21+1 -> 21 | B22: =E21 -> 22525.393 | C22: =Dashboard!B4 -> 500 | D22: =B22*(VLOOKUP(Dashboard!B7,Cenarios!A2:B4,2,FALSE())/100) -> 180.20315 | E22: =B22+C22+D22 -> 23205.596
A23: =A22+1 -> 22 | B23: =E22 -> 23205.596 | C23: =Dashboard!B4 -> 500 | D23: =B23*(VLOOKUP(Dashboard!B7,Cenarios!A2:B4,2,FALSE())/100) -> 185.64477 | E23: =B23+C23+D23 -> 23891.241
A24: =A23+1 -> 23 | B24: =E23 -> 23891.241 | C24: =Dashboard!B4 -> 500 | D24: =B24*(VLOOKUP(Dashboard!B7,Cenarios!A2:B4,2,FALSE())/100) -> 191.12993 | E24: =B24+C24+D24 -> 24582.371
A25: =A24+1 -> 24 | B25: =E24 -> 24582.371 | C25: =Dashboard!B4 -> 500 | D25: =B25*(VLOOKUP(Dashboard!B7,Cenarios!A2:B4,2,FALSE())/100) -> 196.65897 | E25: =B25+C25+D25 -> 25279.03
A26: =A25+1 -> 25 | B26: =E25 -> 25279.03 | C26: =Dashboard!B4 -> 500 | D26: =B26*(VLOOKUP(Dashboard!B7,Cenarios!A2:B4,2,FALSE())/100) -> 202.23224 | E26: =B26+C26+D26 -> 25981.262
A27: =A26+1 -> 26 | B27: =E26 -> 25981.262 | C27: =Dashboard!B4 -> 500 | D27: =B27*(VLOOKUP(Dashboard!B7,Cenarios!A2:B4,2,FALSE())/100) -> 207.8501 | E27: =B27+C27+D27 -> 26689.112
A28: =A27+1 -> 27 | B28: =E27 -> 26689.112 | C28: =Dashboard!B4 -> 500 | D28: =B28*(VLOOKUP(Dashboard!B7,Cenarios!A2:B4,2,FALSE())/100) -> 213.5129 | E28: =B28+C28+D28 -> 27402.625
A29: =A28+1 -> 28 | B29: =E28 -> 27402.625 | C29: =Dashboard!B4 -> 500 | D29: =B29*(VLOOKUP(Dashboard!B7,Cenarios!A2:B4,2,FALSE())/100) -> 219.221 | E29: =B29+C29+D29 -> 28121.846
A30: =A29+1 -> 29 | B30: =E29 -> 28121.846 | C30: =Dashboard!B4 -> 500 | D30: =B30*(VLOOKUP(Dashboard!B7,Cenarios!A2:B4,2,FALSE())/100) -> 224.97477 | E30: =B30+C30+D30 -> 28846.821
A31: =A30+1 -> 30 | B31: =E30 -> 28846.821 | C31: =Dashboard!B4 -> 500 | D31: =B31*(VLOOKUP(Dashboard!B7,Cenarios!A2:B4,2,FALSE())/100) -> 230.77457 | E31: =B31+C31+D31 -> 29577.596
A32: =A31+1 -> 31 | B32: =E31 -> 29577.596 | C32: =Dashboard!B4 -> 500 | D32: =B32*(VLOOKUP(Dashboard!B7,Cenarios!A2:B4,2,FALSE())/100) -> 236.62076 | E32: =B32+C32+D32 -> 30314.216
A33: =A32+1 -> 32 | B33: =E32 -> 30314.216 | C33: =Dashboard!B4 -> 500 | D33: =B33*(VLOOKUP(Dashboard!B7,Cenarios!A2:B4,2,FALSE())/100) -> 242.51373 | E33: =B33+C33+D33 -> 31056.73
A34: =A33+1 -> 33 | B34: =E33 -> 31056.73 | C34: =Dashboard!B4 -> 500 | D34: =B34*(VLOOKUP(Dashboard!B7,Cenarios!A2:B4,2,FALSE())/100) -> 248.45384 | E34: =B34+C34+D34 -> 31805.184
A35: =A34+1 -> 34 | B35: =E34 -> 31805.184 | C35: =Dashboard!B4 -> 500 | D35: =B35*(VLOOKUP(Dashboard!B7,Cenarios!A2:B4,2,FALSE())/100) -> 254.44147 | E35: =B35+C35+D35 -> 32559.625
A36: =A35+1 -> 35 | B36: =E35 -> 32559.625 | C36: =Dashboard!B4 -> 500 | D36: =B36*(VLOOKUP(Dashboard!B7,Cenarios!A2:B4,2,FALSE())/100) -> 260.477 | E36: =B36+C36+D36 -> 33320.102
A37: =A36+1 -> 36 | B37: =E36 -> 33320.102 | C37: =Dashboard!B4 -> 500 | D37: =B37*(VLOOKUP(Dashboard!B7,Cenarios!A2:B4,2,FALSE())/100) -> 266.56082 | E37: =B37+C37+D37 -> 34086.663
A38: =A37+1 -> 37 | B38: =E37 -> 34086.663 | C38: =Dashboard!B4 -> 500 | D38: =B38*(VLOOKUP(Dashboard!B7,Cenarios!A2:B4,2,FALSE())/100) -> 272.69331 | E38: =B38+C38+D38 -> 34859.356
A39: =A38+1 -> 38 | B39: =E38 -> 34859.356 | C39: =Dashboard!B4 -> 500 | D39: =B39*(VLOOKUP(Dashboard!B7,Cenarios!A2:B4,2,FALSE())/100) -> 278.87485 | E39: =B39+C39+D39 -> 35638.231
A40: =A39+1 -> 39 | B40: =E39 -> 35638.231 | C40: =Dashboard!B4 -> 500 | D40: =B40*(VLOOKUP(Dashboard!B7,Cenarios!A2:B4,2,FALSE())/100) -> 285.10585 | E40: =B40+C40+D40 -> 36423.337
...

Sheet Sim_Poupanca
A1: Mês | B1: Saldo Inicial | C1: Aporte | D1: Rendimento | E1: Saldo Final
A2: 1 | B2: =Dashboard!B3 -> 10000 | C2: =Dashboard!B4 -> 500 | D2: =B2*(0.5/100) -> 50 | E2: =B2+C2+D2 -> 10550
A3: =A2+1 -> 2 | B3: =E2 -> 10550 | C3: =Dashboard!B4 -> 500 | D3: =B3*(0.5/100) -> 52.75 | E3: =B3+C3+D3 -> 11102.75
A4: =A3+1 -> 3 | B4: =E3 -> 11102.75 | C4: =Dashboard!B4 -> 500 | D4: =B4*(0.5/100) -> 55.51375 | E4: =B4+C4+D4 -> 11658.264
A5: =A4+1 -> 4 | B5: =E4 -> 11658.264 | C5: =Dashboard!B4 -> 500 | D5: =B5*(0.5/100) -> 58.291319 | E5: =B5+C5+D5 -> 12216.555
A6: =A5+1 -> 5 | B6: =E5 -> 12216.555 | C6: =Dashboard!B4 -> 500 | D6: =B6*(0.5/100) -> 61.082775 | E6: =B6+C6+D6 -> 12777.638
A7: =A6+1 -> 6 | B7: =E6 -> 12777.638 | C7: =Dashboard!B4 -> 500 | D7: =B7*(0.5/100) -> 63.888189 | E7: =B7+C7+D7 -> 13341.526
A8: =A7+1 -> 7 | B8: =E7 -> 13341.526 | C8: =Dashboard!B4 -> 500 | D8: =B8*(0.5/100) -> 66.70763 | E8: =B8+C8+D8 -> 13908.234
A9: =A8+1 -> 8 | B9: =E8 -> 13908.234 | C9: =Dashboard!B4 -> 500 | D9: =B9*(0.5/100) -> 69.541168 | E9: =B9+C9+D9 -> 14477.775
A10: =A9+1 -> 9 | B10: =E9 -> 14477.775 | C10: =Dashboard!B4 -> 500 | D10: =B10*(0.5/100) -> 72.388874 | E10: =B10+C10+D10 -> 15050.164
A11: =A10+1 -> 10 | B11: =E10 -> 15050.164 | C11: =Dashboard!B4 -> 500 | D11: =B11*(0.5/100) -> 75.250819 | E11: =B11+C11+D11 -> 15625.415
A12: =A11+1 -> 11 | B12: =E11 -> 15625.415 | C12: =Dashboard!B4 -> 500 | D12: =B12*(0.5/100) -> 78.127073 | E12: =B12+C12+D12 -> 16203.542
A13: =A12+1 -> 12 | B13: =E12 -> 16203.542 | C13: =Dashboard!B4 -> 500 | D13: =B13*(0.5/100) -> 81.017708 | E13: =B13+C13+D13 -> 16784.559
A14: =A13+1 -> 13 | B14: =E13 -> 16784.559 | C14: =Dashboard!B4 -> 500 | D14: =B14*(0.5/100) -> 83.922797 | E14: =B14+C14+D14 -> 17368.482
A15: =A14+1 -> 14 | B15: =E14 -> 17368.482 | C15: =Dashboard!B4 -> 500 | D15: =B15*(0.5/100) -> 86.842411 | E15: =B15+C15+D15 -> 17955.325
A16: =A15+1 -> 15 | B16: =E15 -> 17955.325 | C16: =Dashboard!B4 -> 500 | D16: =B16*(0.5/100) -> 89.776623 | E16: =B16+C16+D16 -> 18545.101
A17: =A16+1 -> 16 | B17: =E16 -> 18545.101 | C17: =Dashboard!B4 -> 500 | D17: =B17*(0.5/100) -> 92.725506 | E17: =B17+C17+D17 -> 19137.827
A18: =A17+1 -> 17 | B18: =E17 -> 19137.827 | C18: =Dashboard!B4 -> 500 | D18: =B18*(0.5/100) -> 95.689133 | E18: =B18+C18+D18 -> 19733.516
A19: =A18+1 -> 18 | B19: =E18 -> 19733.516 | C19: =Dashboard!B4 -> 500 | D19: =B19*(0.5/100) -> 98.667579 | E19: =B19+C19+D19 -> 20332.183
A20: =A19+1 -> 19 | B20: =E19 -> 20332.183 | C20: =Dashboard!B4 -> 500 | D20: =B20*(0.5/100) -> 101.66092 | E20: =B20+C20+D20 -> 20933.844
A21: =A20+1 -> 20 | B21: =E20 -> 20933.844 | C21: =Dashboard!B4 -> 500 | D21: =B21*(0.5/100) -> 104.66922 | E21: =B21+C21+D21 -> 21538.513
A22: =A21+1 -> 21 | B22: =E21 -> 21538.513 | C22: =Dashboard!B4 -> 500 | D22: =B22*(0.5/100) -> 107.69257 | E22: =B22+C22+D22 -> 22146.206
A23: =A22+1 -> 22 | B23: =E22 -> 22146.206 | C23: =Dashboard!B4 -> 500 | D23: =B23*(0.5/100) -> 110.73103 | E23: =B23+C23+D23 -> 22756.937
A24: =A23+1 -> 23 | B24: =E23 -> 22756.937 | C24: =Dashboard!B4 -> 500 | D24: =B24*(0.5/100) -> 113.78469 | E24: =B24+C24+D24 -> 23370.722
A25: =A24+1 -> 24 | B25: =E24 -> 23370.722 | C25: =Dashboard!B4 -> 500 | D25: =B25*(0.5/100) -> 116.85361 | E25: =B25+C25+D25 -> 23987.575
A26: =A25+1 -> 25 | B26: =E25 -> 23987.575 | C26: =Dashboard!B4 -> 500 | D26: =B26*(0.5/100) -> 119.93788 | E26: =B26+C26+D26 -> 24607.513
A27: =A26+1 -> 26 | B27: =E26 -> 24607.513 | C27: =Dashboard!B4 -> 500 | D27: =B27*(0.5/100) -> 123.03757 | E27: =B27+C27+D27 -> 25230.551
A28: =A27+1 -> 27 | B28: =E27 -> 25230.551 | C28: =Dashboard!B4 -> 500 | D28: =B28*(0.5/100) -> 126.15275 | E28: =B28+C28+D28 -> 25856.704
A29: =A28+1 -> 28 | B29: =E28 -> 25856.704 | C29: =Dashboard!B4 -> 500 | D29: =B29*(0.5/100) -> 129.28352 | E29: =B29+C29+D29 -> 26485.987
A30: =A29+1 -> 29 | B30: =E29 -> 26485.987 | C30: =Dashboard!B4 -> 500 | D30: =B30*(0.5/100) -> 132.42994 | E30: =B30+C30+D30 -> 27118.417
A31: =A30+1 -> 30 | B31: =E30 -> 27118.417 | C31: =Dashboard!B4 -> 500 | D31: =B31*(0.5/100) -> 135.59209 | E31: =B31+C31+D31 -> 27754.009
A32: =A31+1 -> 31 | B32: =E31 -> 27754.009 | C32: =Dashboard!B4 -> 500 | D32: =B32*(0.5/100) -> 138.77005 | E32: =B32+C32+D32 -> 28392.779
A33: =A32+1 -> 32 | B33: =E32 -> 28392.779 | C33: =Dashboard!B4 -> 500 | D33: =B33*(0.5/100) -> 141.9639 | E33: =B33+C33+D33 -> 29034.743
A34: =A33+1 -> 33 | B34: =E33 -> 29034.743 | C34: =Dashboard!B4 -> 500 | D34: =B34*(0.5/100) -> 145.17372 | E34: =B34+C34+D34 -> 29679.917
A35: =A34+1 -> 34 | B35: =E34 -> 29679.917 | C35: =Dashboard!B4 -> 500 | D35: =B35*(0.5/100) -> 148.39958 | E35: =B35+C35+D35 -> 30328.316
A36: =A35+1 -> 35 | B36: =E35 -> 30328.316 | C36: =Dashboard!B4 -> 500 | D36: =B36*(0.5/100) -> 151.64158 | E36: =B36+C36+D36 -> 30979.958
A37: =A36+1 -> 36 | B37: =E36 -> 30979.958 | C37: =Dashboard!B4 -> 500 | D37: =B37*(0.5/100) -> 154.89979 | E37: =B37+C37+D37 -> 31634.858
A38: =A37+1 -> 37 | B38: =E37 -> 31634.858 | C38: =Dashboard!B4 -> 500 | D38: =B38*(0.5/100) -> 158.17429 | E38: =B38+C38+D38 -> 32293.032
A39: =A38+1 -> 38 | B39: =E38 -> 32293.032 | C39: =Dashboard!B4 -> 500 | D39: =B39*(0.5/100) -> 161.46516 | E39: =B39+C39+D39 -> 32954.497
A40: =A39+1 -> 39 | B40: =E39 -> 32954.497 | C40: =Dashboard!B4 -> 500 | D40: =B40*(0.5/100) -> 164.77249 | E40: =B40+C40+D40 -> 33619.27
...
